<?xml version="1.0" encoding="utf-8"?>
<!-- This URDF was automatically created by SolidWorks to URDF Exporter! Originally created by Stephen Brawner (brawner@gmail.com) 
     Commit Version: 1.5.1-0-g916b5db  Build Version: 1.5.7152.31018
     For more information, please see http://wiki.ros.org/sw_urdf_exporter -->
<robot xmlns:xacro="http://www.ros.org/wiki/xacro"
  name="object_disposer_robot">
  <link
    name="base_link">
    <inertial>
      <origin
        xyz="-0.0019576 0.25639 -2.4794E-16"
        rpy="0 0 0" />
      <mass
        value="1618.9" />
      <inertia
        ixx="383.72"
        ixy="-1.7774"
        ixz="-1.9382E-14"
        iyy="902.23"
        iyz="-3.0352E-14"
        izz="593.99" />
    </inertial>
    <visual>
      <origin
        xyz="0 0 0"
        rpy="0 0 0" />
      <geometry>
        <mesh
          filename="package://dql_robot/meshes_object_disposer_robot/base_link.STL" />
      </geometry>
      <material
        name="">
        <color
          rgba="1 0.96471 0.92941 1" />
      </material>
    </visual>
    <collision>
      <origin
        xyz="0 0 0"
        rpy="0 0 0" />
      <geometry>
        <mesh
          filename="package://dql_robot/meshes_object_disposer_robot/base_link.STL" />
      </geometry>
    </collision>
  </link>
  <link
    name="left_front">
    <inertial>
      <origin
        xyz="-1.1102E-16 0.11026 -6.9389E-17"
        rpy="0 0 0" />
      <mass
        value="5.8995" />
      <inertia
        ixx="0.066042"
        ixy="-9.8848E-18"
        ixz="3.5996E-17"
        iyy="0.082271"
        iyz="-1.3851E-16"
        izz="0.066042" />
    </inertial>
    <visual>
      <origin
        xyz="0 0 0"
        rpy="0 0 0" />
      <geometry>
        <mesh
          filename="package://dql_robot/meshes_object_disposer_robot/left_front.STL" />
      </geometry>
      <material
        name="">
        <color
          rgba="0.64706 0.61961 0.58824 1" />
      </material>
    </visual>
    <collision>
      <origin
        xyz="0 0 0.13"
        rpy="0 pi 0" />
      <geometry>
    <cylinder length="0.3" radius="0.12"/>
    </geometry>
    </collision>
  </link>
  <joint
    name="lf"
    type="continuous">
    <origin
      xyz="-0.55 -0.799831099463414 0.1"
      rpy="3.14159265358979 0.0340014978182163 0" />
    <parent
      link="base_link" />
    <child
      link="left_front" />
    <axis
      xyz="0 1 0" />
  </joint>
  <link
    name="left_front_r">
    <inertial>
      <origin
        xyz="-3.33066907387547E-16 2.77555756156289E-17 0.112077014459711"
        rpy="0 0 0" />
      <mass
        value="13.6879351423523" />
      <inertia
        ixx="0.301179544297615"
        ixy="3.46944695195361E-18"
        ixz="3.35401616298055E-19"
        iyy="0.301179544297615"
        iyz="-1.60084094021532E-21"
        izz="0.602237244546673" />
    </inertial>
    <visual>
      <origin
        xyz="0 0 0"
        rpy="0 0 0" />
      <geometry>
        <mesh
          filename="package://dql_robot/meshes_object_disposer_robot/left_front_r.STL" />
      </geometry>
      <material
        name="">
        <color
          rgba="0.294117647058824 0.294117647058824 0.294117647058824 1" />
      </material>
    </visual>
    <collision>
      <origin
        xyz="0 0 0.13"
        rpy="0 0 0" />
      <geometry>
    <cylinder length="0.3" radius="0.25"/>
    </geometry>
    </collision>
  </link>
  <joint
    name="lfr"
    type="fixed">
    <origin
      xyz="0 0 0"
      rpy="-1.5707963267949 -0.0227400198201913 0" />
    <parent
      link="left_front" />
    <child
      link="left_front_r" />
    <axis
      xyz="0 0 1" />
  </joint>
  <link
    name="left_back">
    <inertial>
      <origin
        xyz="0 0.110260672582107 -1.38777878078145E-17"
        rpy="0 0 0" />
      <mass
        value="5.8995249500979" />
      <inertia
        ixx="0.0660416392695462"
        ixy="-6.22509739521811E-18"
        ixz="-3.55618312575245E-17"
        iyy="0.0822711285244961"
        iyz="-2.1254645438188E-17"
        izz="0.0660416392695462" />
    </inertial>
    <visual>
      <origin
        xyz="0 0 0"
        rpy="0 0 0" />
      <geometry>
        <mesh
          filename="package://dql_robot/meshes_object_disposer_robot/left_back.STL" />
      </geometry>
      <material
        name="">
        <color
          rgba="0.647058823529412 0.619607843137255 0.588235294117647 1" />
      </material>
    </visual>
    <collision>
      <origin
        xyz="0 0 0.13"
        rpy="0 pi 0" />
      <geometry>
    <cylinder length="0.3" radius="0.12"/>
    </geometry>
    </collision>
  </link>
  <joint
    name="lb"
    type="continuous">
    <origin
      xyz="0.7 -0.799831099463414 0.1"
      rpy="3.14159265358979 -0.102399660441991 0" />
    <parent
      link="base_link" />
    <child
      link="left_back" />
    <axis
      xyz="0 1 0" />
  </joint>
  <link
    name="left_back_r">
    <inertial>
      <origin
        xyz="2.22044604925031E-16 0 0.112077014459711"
        rpy="0 0 0" />
      <mass
        value="13.6879351423523" />
      <inertia
        ixx="0.301179544297614"
        ixy="-6.62307976283294E-34"
        ixz="-1.56233555452374E-19"
        iyy="0.301179544297614"
        iyz="2.86037026133878E-33"
        izz="0.602237244546671" />
    </inertial>
    <visual>
      <origin
        xyz="0 0 0"
        rpy="0 0 0" />
      <geometry>
        <mesh
          filename="package://dql_robot/meshes_object_disposer_robot/left_back_r.STL" />
      </geometry>
      <material
        name="">
        <color
          rgba="0.294117647058824 0.294117647058824 0.294117647058824 1" />
      </material>
    </visual>
    <collision>
      <origin
        xyz="0 0 0.13"
        rpy="0 0 0" />
      <geometry>
    <cylinder length="0.3" radius="0.25"/>
    </geometry>
    </collision>
  </link>
  <joint
    name="lbr"
    type="fixed">
    <origin
      xyz="0 0 0"
      rpy="-1.5707963267949 -0.102399660441991 0" />
    <parent
      link="left_back" />
    <child
      link="left_back_r" />
    <axis
      xyz="0 0 1" />
  </joint>
  <link
    name="right_front">
    <inertial>
      <origin
        xyz="-1.11022302462516E-16 -0.110077128491063 -5.55111512312578E-17"
        rpy="0 0 0" />
      <mass
        value="5.89952495009792" />
      <inertia
        ixx="0.0660416392695464"
        ixy="-3.08263549304373E-17"
        ixz="8.67361737988404E-18"
        iyy="0.0822711285244962"
        iyz="1.22308571645207E-18"
        izz="0.0660416392695464" />
    </inertial>
    <visual>
      <origin
        xyz="0 0 0"
        rpy="0 0 0" />
      <geometry>
        <mesh
          filename="package://dql_robot/meshes_object_disposer_robot/right_front.STL" />
      </geometry>
      <material
        name="">
        <color
          rgba="0.647058823529412 0.619607843137255 0.588235294117647 1" />
      </material>
    </visual>
    <collision>
      <origin
        xyz="0 0 0.13"
        rpy="0 pi 0" />
      <geometry>
    <cylinder length="0.3" radius="0.12"/>
    </geometry>
    </collision>
  </link>
  <joint
    name="rf"
    type="continuous">
    <origin
      xyz="-0.55 0.799831099463415 0.1"
      rpy="3.14159265358979 0.300637698629984 0" />
    <parent
      link="base_link" />
    <child
      link="right_front" />
    <axis
      xyz="0 1 0" />
  </joint>
  <link
    name="right_front_r">
    <inertial>
      <origin
        xyz="-1.11022302462516E-16 1.38777878078145E-17 -0.10826078661346"
        rpy="0 0 0" />
      <mass
        value="13.6879351423523" />
      <inertia
        ixx="0.301179544297615"
        ixy="-6.62307976283288E-34"
        ixz="-7.4918392515965E-20"
        iyy="0.301179544297615"
        iyz="2.7597698853022E-33"
        izz="0.602237244546672" />
    </inertial>
    <visual>
      <origin
        xyz="0 0 0"
        rpy="0 0 0" />
      <geometry>
        <mesh
          filename="package://dql_robot/meshes_object_disposer_robot/right_front_r.STL" />
      </geometry>
      <material
        name="">
        <color
          rgba="0.294117647058824 0.294117647058824 0.294117647058824 1" />
      </material>
    </visual>
    <collision>
      <origin
        xyz="0 0 -0.13"
        rpy="0 0 0" />
      <geometry>
    <cylinder length="0.3" radius="0.25"/>
    </geometry>
    </collision>
  </link>
  <joint
    name="rfr"
    type="fixed">
    <origin
      xyz="0 0 0"
      rpy="-1.5707963267949 0.300637698629984 0" />
    <parent
      link="right_front" />
    <child
      link="right_front_r" />
    <axis
      xyz="0 0 1" />
  </joint>
  <link
    name="right_back">
    <inertial>
      <origin
        xyz="-1.11022302462516E-16 -0.110077128491064 -1.11022302462516E-16"
        rpy="0 0 0" />
      <mass
        value="5.8995249500979" />
      <inertia
        ixx="0.0660416392695463"
        ixy="1.28854883228115E-17"
        ixz="1.45283091113058E-17"
        iyy="0.0822711285244963"
        iyz="-5.69353211695258E-17"
        izz="0.0660416392695463" />
    </inertial>
    <visual>
      <origin
        xyz="0 0 0"
        rpy="0 0 0" />
      <geometry>
        <mesh
          filename="package://dql_robot/meshes_object_disposer_robot/right_back.STL" />
      </geometry>
      <material
        name="">
        <color
          rgba="0.647058823529412 0.619607843137255 0.588235294117647 1" />
      </material>
    </visual>
    <collision>
      <origin
        xyz="0 0 -0.13"
        rpy="0 pi 0" />
      <geometry>
    <cylinder length="0.3" radius="0.12"/>
    </geometry>
    </collision>
  </link>
  <joint
    name="rv"
    type="continuous">
    <origin
      xyz="0.7 0.799831099463415 0.1"
      rpy="3.14159265358979 0.0278736429806845 0" />
    <parent
      link="base_link" />
    <child
      link="right_back" />
    <axis
      xyz="0 1 0" />
  </joint>
  <link
    name="right_back_r">
    <inertial>
      <origin
        xyz="-1.11022302462516E-16 -2.77555756156289E-17 -0.10826078661346"
        rpy="0 0 0" />
      <mass
        value="13.6879351423523" />
      <inertia
        ixx="0.301179544297615"
        ixy="-6.62307976283288E-34"
        ixz="-7.4918392515965E-20"
        iyy="0.301179544297615"
        iyz="2.75104744361933E-33"
        izz="0.602237244546673" />
    </inertial>
    <visual>
      <origin
        xyz="0 0 0"
        rpy="0 0 0" />
      <geometry>
        <mesh
          filename="package://dql_robot/meshes_object_disposer_robot/right_back_r.STL" />
      </geometry>
      <material
        name="">
        <color
          rgba="0.294117647058824 0.294117647058824 0.294117647058824 1" />
      </material>
    </visual>
    <collision>
      <origin
        xyz="0 0 -0.13"
        rpy="0 0 0" />
      <geometry>
    <cylinder length="0.3" radius="0.25"/>
    </geometry>
    </collision>
  </link>
  <joint
    name="rbr"
    type="fixed">
    <origin
      xyz="0 0 0"
      rpy="-1.5707963267949 0.0278736429806845 0" />
    <parent
      link="right_back" />
    <child
      link="right_back_r" />
    <axis
      xyz="0 0 1" />
  </joint>

  <gazebo reference="base_link">
    <material>Gazebo/SkyBlue      </material>
  </gazebo>

  <gazebo reference="right_back_r">
    <material>Gazebo/Black </material>
  </gazebo>

  <gazebo reference="right_front_r">
    <material>Gazebo/Black </material>
  </gazebo>

  <gazebo reference="left_back_r">
    <material>Gazebo/Black </material>
  </gazebo>

  <gazebo reference="left_front_r">
    <material>Gazebo/Black </material>
  </gazebo>

  <gazebo reference="right_back">
    <material>Gazebo/ZincYellow  </material>
  </gazebo>

  <gazebo reference="right_front">
    <material>Gazebo/ZincYellow  </material>
  </gazebo>

  <gazebo reference="left_back">
    <material>Gazebo/ZincYellow  </material>
  </gazebo>

  <gazebo reference="left_front">
    <material>Gazebo/ZincYellow  </material>
  </gazebo>

<gazebo reference="lf"/>
<gazebo reference="rf"/>
<gazebo reference="lb"/>
<gazebo reference="rv"/>

<gazebo>
  <plugin name="skid_steer_drive_controller" filename="libgazebo_ros_skid_steer_drive.so">
    <updateRate>100.0</updateRate>
    <!--<robotNamespace>/</robotNamespace>-->
    <leftFrontJoint>lf</leftFrontJoint>
    <rightFrontJoint>rf</rightFrontJoint>
    <leftRearJoint>lb</leftRearJoint>
    <rightRearJoint>rv</rightRearJoint>
    <wheelSeparation>1.6</wheelSeparation>
    <wheelDiameter>0.5</wheelDiameter>
    <robotBaseFrame>base_link</robotBaseFrame>
    <commandTopic>cmd_vel_car</commandTopic>
    <torque>2000</torque>
    <topicName>cmd_vel_car</topicName>
    <broadcastTF>false</broadcastTF>
  </plugin>
</gazebo>
 

  <link name="camera_link1">
    <collision>
      <origin xyz="0 0 0" rpy="0 0 0"/>
      <geometry>
    <box size="0.1 0.1 0.1"/>
      </geometry>
    </collision>

    <visual>
      <origin xyz="0 0 0" rpy="0 0 0"/>
      <geometry>
    <box size="0.1 0.1 0.1"/>
      </geometry>
      <material name="red"/>
    </visual>

    <inertial>
      <mass value="1e-5" />
      <origin xyz="0 0 0" rpy="0 0 0"/>
      <inertia ixx="1e-6" ixy="0" ixz="0" iyy="1e-6" iyz="0" izz="1e-6" />
    </inertial>
  </link>

  <joint name="camera_joint1" type="fixed">
    <axis xyz="0 -1 0" />
    <origin xyz="-0.8 0.0 1.0" rpy="0 0.45 3.14"/>
    <parent link="base_link"/>
    <child link="camera_link1"/>
  </joint>

<link name="camera_link2">
    <collision>
      <origin xyz="0 0 0" rpy="0 0 0"/>
      <geometry>
    <box size="0.1 0.1 0.1"/>
      </geometry>
    </collision>

    <visual>
      <origin xyz="0 0 0" rpy="0 0 0"/>
      <geometry>
    <box size="0.1 0.1 0.1"/>
      </geometry>
      <material name="red"/>
    </visual>

    <inertial>
      <mass value="1e-5" />
      <origin xyz="0 0 0" rpy="0 0 0"/>
      <inertia ixx="1e-6" ixy="0" ixz="0" iyy="1e-6" iyz="0" izz="1e-6" />
    </inertial>
  </link>

  <joint name="camera_joint2" type="fixed">
    <axis xyz="0 -1 0" />
    <origin xyz="-20.0 0.0 12.0" rpy="0 1.545 3.14"/>
    <parent link="base_link"/>
    <child link="camera_link2"/>
  </joint>

 <gazebo reference="camera_link1">
    <sensor type="camera" name="camera1">
      <update_rate>30.0</update_rate>
      <camera name="head">
        <horizontal_fov>1.3</horizontal_fov>
        <image>
          <width>640</width>
          <height>480</height>
          <format>R8G8B8</format>
        </image>
        <clip>
          <near>0.15</near>
          <far>300</far>
        </clip>
        <noise>
          <type>gaussian</type>
          <!-- Noise is sampled independently per pixel on each frame.
               That pixel's noise value is added to each of its color
               channels, which at that point lie in the range [0,1]. -->
          <mean>0.0</mean>
          <stddev>0.007</stddev>
        </noise>
      </camera>
      <plugin name="camera_controller" filename="libgazebo_ros_camera.so">
        <alwaysOn>true</alwaysOn>
        <updateRate>0.0</updateRate>
        <cameraName>/front_camera</cameraName>
        <imageTopicName>image_raw</imageTopicName>
        <cameraInfoTopicName>camera_info</cameraInfoTopicName>
        <frameName>camera_link1</frameName>
        <hackBaseline>0.07</hackBaseline>
        <distortionK1>0.0</distortionK1>
        <distortionK2>0.0</distortionK2>
        <distortionK3>0.0</distortionK3>
        <distortionT1>0.0</distortionT1>
        <distortionT2>0.0</distortionT2>
      </plugin>
    </sensor>
  </gazebo>

   <gazebo reference="camera_link2">
    <sensor type="camera" name="camera2">
      <update_rate>30.0</update_rate>
      <camera name="head">
        <horizontal_fov>2.5</horizontal_fov>
        <image>
          <width>640</width>
          <height>480</height>
          <format>R8G8B8</format>
        </image>
        <clip>
          <near>0.15</near>
          <far>300</far>
        </clip>
        <noise>
          <type>gaussian</type>
          <!-- Noise is sampled independently per pixel on each frame.
               That pixel's noise value is added to each of its color
               channels, which at that point lie in the range [0,1]. -->
          <mean>0.0</mean>
          <stddev>0.007</stddev>
        </noise>
      </camera>
      <plugin name="camera_controller" filename="libgazebo_ros_camera.so">
        <alwaysOn>true</alwaysOn>
        <updateRate>0.0</updateRate>
        <cameraName>/top_camera</cameraName>
        <imageTopicName>image_raw</imageTopicName>
        <cameraInfoTopicName>camera_info</cameraInfoTopicName>
        <frameName>camera_link1</frameName>
        <hackBaseline>0.07</hackBaseline>
        <distortionK1>0.0</distortionK1>
        <distortionK2>0.0</distortionK2>
        <distortionK3>0.0</distortionK3>
        <distortionT1>0.0</distortionT1>
        <distortionT2>0.0</distortionT2>
      </plugin>
    </sensor>
  </gazebo>

<!-- camera-->
<xacro:property name="camera_link1" value="0.05" /> <!-- Size of square 'camera' box -->
<xacro:property name="camera_link2" value="0.05" /> <!-- Size of square 'camera' box -->

<!-- lazer scanner -->
<!--
<xacro:include filename="$(find dql_robot)/urdf/object_disposer_robot/hokuyo.xacro"/>
<xacro:laser name="base_laser" parent="base_link" xyz="-1.0 0 0.21" rpy="0 0 40.9" meshes="package://gazebo_plugins/test/multi_robot_scenario/meshes/laser"/>
-->


</robot>
